<?xml version="1.0" ?>
<!-- =================================================================================== -->
<!-- |    This document was autogenerated by xacro from nifti_robot.xacro              | -->
<!-- |    EDITING THIS FILE BY HAND IS NOT RECOMMENDED                                 | -->
<!-- =================================================================================== -->
<robot name="NIFTi">
  <!-- MEASURED CONSTANTS -->
  <!-- SPECIAL LINKS -->
  <!-- This is a virtual link that specifies the origin to which parts attachable to the top of the robot should be related. -->
  <link name="rear_right_box"/>
  <joint name="rear_right_box_j" type="fixed">
    <parent link="base_link"/>
    <child link="rear_right_box"/>
    <origin rpy="0 0 0" xyz="-0.379 -0.1265 0.185"/>
  </joint>
  <!-- INCLUDES -->
  <!-- The included models should have collision elements specified for all physical links to be filtered out by laser filtering. -->
  <!-- MACRO SPECIFICATIONS -->
  <!-- NIFTI ROBOT LINKS AND JOINTS SPECIFICATION -->
  <link name="base_link">
    <visual>
      <origin rpy="0 0 0" xyz="0 0 0"/>
      <geometry>
        <mesh filename="package://nifti_robot_description/meshes/body.dae" scale="1.0 1.0 1.0"/>
      </geometry>
    </visual>
    <collision>
      <origin rpy="0 0 0" xyz="-0.1220 0 0.118"/>
      <geometry>
        <box size="0.50017 0.24093 0.1390"/>
      </geometry>
    </collision>
    <collision>
      <origin rpy="0 0 0" xyz="0.157 0 0.118"/>
      <geometry>
        <box size="0.056 0.12093 0.1390"/>
      </geometry>
    </collision>
    <collision>
      <origin rpy="0 0 0.785398" xyz="0.144 -0.076 0.118"/>
      <geometry>
        <box size="0.083 0.040 0.1390"/>
      </geometry>
    </collision>
    <collision>
      <origin rpy="0 0 -0.785398" xyz="0.144 0.076 0.118"/>
      <geometry>
        <box size="0.083 0.040 0.1390"/>
      </geometry>
    </collision>
    <collision>
      <origin rpy="0 0 0" xyz="0 0.135 0.09"/>
      <geometry>
        <box size="0.055 0.040 0.08"/>
      </geometry>
    </collision>
    <collision>
      <origin rpy="0 0 0" xyz="0 0.155 0.013"/>
      <geometry>
        <box size="0.055 0.020 0.075"/>
      </geometry>
    </collision>
    <collision>
      <origin rpy="0 0 0" xyz="0 -0.135 0.09"/>
      <geometry>
        <box size="0.055 0.040 0.08"/>
      </geometry>
    </collision>
    <collision>
      <origin rpy="0 0 0" xyz="0 -0.155 0.013"/>
      <geometry>
        <box size="0.055 0.020 0.075"/>
      </geometry>
    </collision>
    <collision>
      <origin rpy="0 0 0" xyz="-0.13 0 0.418"/>
      <geometry>
        <box size="0.65 0.35 0.6"/>
      </geometry>
    </collision>
    <inertial>
      <origin rpy="0 0 0" xyz="-0.034 0 0.142"/>
      <mass value="6.746"/>
      <inertia ixx="0.0069904" ixy="0.00012271" ixz="-4.2725e-05" iyy="0.02129" iyz="-0.00010522" izz="0.025519"/>
    </inertial>
  </link>
  <link name="battery">
    <visual>
      <origin rpy="0 0 0" xyz="0 0 0"/>
      <geometry>
        <mesh filename="package://nifti_robot_description/meshes/battery.dae" scale="1.0 1.0 1.0"/>
      </geometry>
    </visual>
    <collision>
      <origin rpy="0 0 0" xyz="0 0 0.0410"/>
      <geometry>
        <box size="0.1450 0.1350 0.0820"/>
      </geometry>
    </collision>
    <inertial>
      <origin rpy="0 0 0" xyz="0 0 0.041"/>
      <mass value="3.18"/>
      <inertia ixx="0.0020793" ixy="0.0" ixz="0.0" iyy="0.0023127" iyz="0.0" izz="0.0032712"/>
    </inertial>
  </link>
  <joint name="battery_j" type="fixed">
    <parent link="base_link"/>
    <child link="battery"/>
    <origin rpy="0 0 0" xyz="-0.2836 -0.0221 0.0722"/>
  </joint>
  <link name="top_box">
    <visual>
      <origin rpy="0 0 0" xyz="0 0 0"/>
      <geometry>
        <mesh filename="package://nifti_robot_description/meshes/top_box.dae" scale="1.0 1.0 1.0"/>
      </geometry>
    </visual>
    <collision>
      <origin rpy="0 0 0" xyz="-0.0290 0 0.0315"/>
      <geometry>
        <box size="0.2000 0.1330 0.06252"/>
      </geometry>
    </collision>
    <collision>
      <origin rpy="0 0 0" xyz="-0.09824 0.04127 0.0690"/>
      <geometry>
        <box size="0.0440 0.0440 0.01303"/>
      </geometry>
    </collision>
    <collision>
      <origin rpy="0 0 0" xyz="-0.07383 -0.04222 0.07996"/>
      <geometry>
        <box size="0.03732 0.03523 0.03489"/>
      </geometry>
    </collision>
    <inertial>
      <origin rpy="0 0 0" xyz="0 0 0.041"/>
      <mass value="0.24"/>
      <inertia ixx="0.0026136" ixy="0.0" ixz="0.0" iyy="0.0049426" iyz="0.0" izz="0.0070334"/>
    </inertial>
  </link>
  <joint name="top_box_j" type="fixed">
    <parent link="rear_right_box"/>
    <child link="top_box"/>
    <!-- Origin of top box is 0.071 m from the front side. And top_box_j_x is distance from robot's back to top box' front. -->
    <origin rpy="0 0 0" xyz="0.42669999999999997 0.0708 0.0"/>
  </joint>
  <link name="antenna">
    <visual>
      <origin rpy="0 0 0" xyz="0 0 0"/>
      <geometry>
        <mesh filename="package://nifti_robot_description/meshes/antenna.dae" scale="1.0 1.0 1.0"/>
      </geometry>
    </visual>
    <collision>
      <origin rpy="0 1.5707963267 0" xyz="-0.01864 0 0"/>
      <geometry>
        <cylinder length="0.03718" radius="0.008"/>
      </geometry>
    </collision>
    <collision>
      <origin rpy="0 0 0" xyz="-0.030 0 0.19053"/>
      <geometry>
        <cylinder length="0.38107" radius="0.008"/>
      </geometry>
    </collision>
    <inertial>
      <origin rpy="0 0 0" xyz="-0.022 0.0203 0.02917"/>
      <mass value="0.56"/>
      <inertia ixx="0.004878" ixy="-6.2341e-07" ixz="-7.4538e-07" iyy="0.00090164" iyz="-0.00014394" izz="0.0042946"/>
    </inertial>
  </link>
  <joint name="antenna_j" type="fixed">
    <parent link="base_link"/>
    <child link="antenna"/>
    <origin rpy="0 0 0" xyz="-0.3720 0.0789 0.1551"/>
  </joint>
  <link name="left_track">
    <visual>
      <origin rpy="1.5707963267 0 1.5707963267" xyz="0 0 -0.0705"/>
      <geometry>
        <mesh filename="package://nifti_robot_description/meshes/bogie.dae" scale="1.0 1.0 1.0"/>
      </geometry>
    </visual>
    <collision>
      <origin rpy="1.5707963267 0 1.5707963267" xyz="0 0 0.01855"/>
      <geometry>
        <box size="0.09728 0.18094 0.50000"/>
      </geometry>
    </collision>
    <collision>
      <origin rpy="1.5707963267 0 0" xyz="0.25 -0.015 0.01855"/>
      <geometry>
        <!-- enlarged because of laser filtering problems -->
        <cylinder length="0.11228" radius="0.09047"/>
      </geometry>
    </collision>
    <collision>
      <origin rpy="1.5707963267 0 0" xyz="-0.25 0 0.01855"/>
      <geometry>
        <cylinder length="0.09728" radius="0.09047"/>
      </geometry>
    </collision>
    <inertial>
      <origin rpy="0 0 0" xyz="0 0 0.0141"/>
      <mass value="6.06"/>
      <inertia ixx="0.002731" ixy="0.0" ixz="0.0" iyy="0.032554" iyz="1.5e-05" izz="0.031391"/>
    </inertial>
  </link>
  <joint name="left_track_j" type="revolute">
    <parent link="base_link"/>
    <child link="left_track"/>
    <axis xyz="0 1 0"/>
    <origin rpy="0 0.0 0" xyz="0 0.1985 0"/>
    <limit effort="0" lower="0" upper="0" velocity="4"/>
    <!--<limit lower="-0.7" upper="0.7" effort="0" velocity="4" />-->
  </joint>
  <link name="right_track">
    <visual>
      <origin rpy="1.5707963267 0 -1.5707963267" xyz="0 0 -0.0705"/>
      <geometry>
        <mesh filename="package://nifti_robot_description/meshes/bogie.dae" scale="1.0 1.0 1.0"/>
      </geometry>
    </visual>
    <collision>
      <origin rpy="1.5707963267 0 1.5707963267" xyz="0 0 0.01855"/>
      <geometry>
        <box size="0.09728 0.18094 0.50000"/>
      </geometry>
    </collision>
    <collision>
      <origin rpy="1.5707963267 0 0" xyz="0.25 0.015 0.01855"/>
      <geometry>
        <!-- enlarged because of laser filtering problems -->
        <cylinder length="0.11228" radius="0.09047"/>
      </geometry>
    </collision>
    <collision>
      <origin rpy="1.5707963267 0 0" xyz="-0.25 0 0.01855"/>
      <geometry>
        <cylinder length="0.09728" radius="0.09047"/>
      </geometry>
    </collision>
    <inertial>
      <origin rpy="0 0 0" xyz="0 0 0.0141"/>
      <mass value="6.06"/>
      <inertia ixx="0.002731" ixy="0.0" ixz="0.0" iyy="0.032554" iyz="1.5e-05" izz="0.031391"/>
    </inertial>
  </link>
  <joint name="right_track_j" type="revolute">
    <parent link="base_link"/>
    <child link="right_track"/>
    <axis xyz="0 1 0"/>
    <origin rpy="0 0.0 0" xyz="0 -0.1985 0"/>
    <limit effort="0" lower="0" upper="0" velocity="4"/>
    <!--<limit lower="-0.7" upper="0.7" effort="0" velocity="4" />-->
  </joint>
  <link name="front_left_flipper">
    <visual>
      <origin rpy="3.32575 0 1.5707963267" xyz="0 0 0"/>
      <geometry>
        <mesh filename="package://nifti_robot_description/meshes/flipper.dae" scale="1.0 1.0 1.0"/>
      </geometry>
    </visual>
    <collision>
      <origin rpy="1.5707963267 0 0" xyz="0 -0.0085 0"/>
      <geometry>
        <cylinder length="0.06681000000000001" radius="0.09047"/>
      </geometry>
    </collision>
    <collision>
      <origin rpy="1.5707963267 0 0" xyz="0.33 -0.0085 0.0"/>
      <geometry>
        <cylinder length="0.06681000000000001" radius="0.029"/>
      </geometry>
    </collision>
    <collision>
      <origin rpy="0 0.184162095 0.0" xyz="0.165 -0.0085 0.0325"/>
      <geometry>
        <box size="0.33 0.06681000000000001 0.055"/>
      </geometry>
    </collision>
    <collision>
      <origin rpy="0 -0.184162095 0.0" xyz="0.165 -0.0085 -0.0325"/>
      <geometry>
        <box size="0.33 0.06681000000000001 0.055"/>
      </geometry>
    </collision>
    <collision>
      <origin rpy="0 -0.02 0.0" xyz="0.136 -0.0085 0.004"/>
      <geometry>
        <box size="0.20 0.06681000000000001 0.07"/>
      </geometry>
    </collision>
    <inertial>
      <origin rpy="0 0 0" xyz="0.08 0 0.0"/>
      <mass value="0.75"/>
      <inertia ixx="0.0017491" ixy="2.8512e-07" ixz="0.0018277" iyy="0.012277" iyz="-3.6288e-07" izz="0.010941"/>
    </inertial>
    <sensor name="front_left_flipper_contact" type="contact">
      <contact>
        <collision>front_left_flipper_collision</collision>
        <collision>front_left_flipper_collision_large_wheel</collision>
        <collision>front_left_flipper_collision_small_wheel</collision>
        <collision>front_left_flipper_collision_top_bar</collision>
        <collision>front_left_flipper_collision_bottom_bar</collision>
        <collision>front_left_flipper_collision_middle_bar</collision>
      </contact>
    </sensor>
  </link>
  <joint name="front_left_flipper_j" type="continuous">
    <parent link="left_track"/>
    <child link="front_left_flipper"/>
    <axis xyz="0 1 0"/>
    <origin rpy="0 0.1937 0" xyz="0.25 0.0735 0.0195"/>
  </joint>
  <link name="front_right_flipper">
    <visual>
      <origin rpy="3.32575 0 -1.5707963267" xyz="0 0 0"/>
      <geometry>
        <mesh filename="package://nifti_robot_description/meshes/flipper.dae" scale="1.0 1.0 1.0"/>
      </geometry>
    </visual>
    <collision>
      <origin rpy="1.5707963267 0 0" xyz="0 0.0085 0"/>
      <geometry>
        <cylinder length="0.06681000000000001" radius="0.09047"/>
      </geometry>
    </collision>
    <collision>
      <origin rpy="1.5707963267 0 0" xyz="-0.33 0.0085 0.0"/>
      <geometry>
        <cylinder length="0.06681000000000001" radius="0.029"/>
      </geometry>
    </collision>
    <collision>
      <origin rpy="0 0.184162095 3.1415926534" xyz="-0.165 0.0085 0.0325"/>
      <geometry>
        <box size="0.33 0.06681000000000001 0.055"/>
      </geometry>
    </collision>
    <collision>
      <origin rpy="0 -0.184162095 3.1415926534" xyz="-0.165 0.0085 -0.0325"/>
      <geometry>
        <box size="0.33 0.06681000000000001 0.055"/>
      </geometry>
    </collision>
    <collision>
      <origin rpy="0 -0.02 3.1415926534" xyz="-0.136 0.0085 0.004"/>
      <geometry>
        <box size="0.20 0.06681000000000001 0.07"/>
      </geometry>
    </collision>
    <inertial>
      <origin rpy="0 0 0" xyz="-0.08 0 0.0"/>
      <mass value="0.75"/>
      <inertia ixx="0.0017491" ixy="2.8512e-07" ixz="0.0018277" iyy="0.012277" iyz="-3.6288e-07" izz="0.010941"/>
    </inertial>
    <sensor name="front_right_flipper_contact" type="contact">
      <contact>
        <collision>front_right_flipper_collision</collision>
        <collision>front_right_flipper_collision_large_wheel</collision>
        <collision>front_right_flipper_collision_small_wheel</collision>
        <collision>front_right_flipper_collision_top_bar</collision>
        <collision>front_right_flipper_collision_bottom_bar</collision>
        <collision>front_right_flipper_collision_middle_bar</collision>
      </contact>
    </sensor>
  </link>
  <joint name="front_right_flipper_j" type="continuous">
    <parent link="right_track"/>
    <child link="front_right_flipper"/>
    <axis xyz="0 1 0"/>
    <origin rpy="0 -2.9479 0" xyz="0.25 -0.0735 0.0195"/>
  </joint>
  <link name="rear_left_flipper">
    <visual>
      <origin rpy="3.32575 0 1.5707963267" xyz="0 0 0"/>
      <geometry>
        <mesh filename="package://nifti_robot_description/meshes/flipper.dae" scale="1.0 1.0 1.0"/>
      </geometry>
    </visual>
    <collision>
      <origin rpy="1.5707963267 0 0" xyz="0 -0.0 0"/>
      <geometry>
        <cylinder length="0.04981" radius="0.09047"/>
      </geometry>
    </collision>
    <collision>
      <origin rpy="1.5707963267 0 0" xyz="0.33 -0.0 0.0"/>
      <geometry>
        <cylinder length="0.04981" radius="0.029"/>
      </geometry>
    </collision>
    <collision>
      <origin rpy="0 0.184162095 0.0" xyz="0.165 -0.0 0.0325"/>
      <geometry>
        <box size="0.33 0.04981 0.055"/>
      </geometry>
    </collision>
    <collision>
      <origin rpy="0 -0.184162095 0.0" xyz="0.165 -0.0 -0.0325"/>
      <geometry>
        <box size="0.33 0.04981 0.055"/>
      </geometry>
    </collision>
    <collision>
      <origin rpy="0 -0.02 0.0" xyz="0.136 -0.0 0.004"/>
      <geometry>
        <box size="0.20 0.04981 0.07"/>
      </geometry>
    </collision>
    <inertial>
      <origin rpy="0 0 0" xyz="0.08 0 0.0"/>
      <mass value="0.75"/>
      <inertia ixx="0.0017491" ixy="2.8512e-07" ixz="0.0018277" iyy="0.012277" iyz="-3.6288e-07" izz="0.010941"/>
    </inertial>
    <sensor name="rear_left_flipper_contact" type="contact">
      <contact>
        <collision>rear_left_flipper_collision</collision>
        <collision>rear_left_flipper_collision_large_wheel</collision>
        <collision>rear_left_flipper_collision_small_wheel</collision>
        <collision>rear_left_flipper_collision_top_bar</collision>
        <collision>rear_left_flipper_collision_bottom_bar</collision>
        <collision>rear_left_flipper_collision_middle_bar</collision>
      </contact>
    </sensor>
  </link>
  <joint name="rear_left_flipper_j" type="continuous">
    <parent link="left_track"/>
    <child link="rear_left_flipper"/>
    <axis xyz="0 1 0"/>
    <origin rpy="0 2.9479 0" xyz="-0.25 0.0735 0.0195"/>
  </joint>
  <link name="rear_right_flipper">
    <visual>
      <origin rpy="3.32575 0 -1.5707963267" xyz="0 0 0"/>
      <geometry>
        <mesh filename="package://nifti_robot_description/meshes/flipper.dae" scale="1.0 1.0 1.0"/>
      </geometry>
    </visual>
    <collision>
      <origin rpy="1.5707963267 0 0" xyz="0 0.0 0"/>
      <geometry>
        <cylinder length="0.04981" radius="0.09047"/>
      </geometry>
    </collision>
    <collision>
      <origin rpy="1.5707963267 0 0" xyz="-0.33 0.0 0.0"/>
      <geometry>
        <cylinder length="0.04981" radius="0.029"/>
      </geometry>
    </collision>
    <collision>
      <origin rpy="0 0.184162095 3.1415926534" xyz="-0.165 0.0 0.0325"/>
      <geometry>
        <box size="0.33 0.04981 0.055"/>
      </geometry>
    </collision>
    <collision>
      <origin rpy="0 -0.184162095 3.1415926534" xyz="-0.165 0.0 -0.0325"/>
      <geometry>
        <box size="0.33 0.04981 0.055"/>
      </geometry>
    </collision>
    <collision>
      <origin rpy="0 -0.02 3.1415926534" xyz="-0.136 0.0 0.004"/>
      <geometry>
        <box size="0.20 0.04981 0.07"/>
      </geometry>
    </collision>
    <inertial>
      <origin rpy="0 0 0" xyz="-0.08 0 0.0"/>
      <mass value="0.75"/>
      <inertia ixx="0.0017491" ixy="2.8512e-07" ixz="0.0018277" iyy="0.012277" iyz="-3.6288e-07" izz="0.010941"/>
    </inertial>
    <sensor name="rear_right_flipper_contact" type="contact">
      <contact>
        <collision>rear_right_flipper_collision</collision>
        <collision>rear_right_flipper_collision_large_wheel</collision>
        <collision>rear_right_flipper_collision_small_wheel</collision>
        <collision>rear_right_flipper_collision_top_bar</collision>
        <collision>rear_right_flipper_collision_bottom_bar</collision>
        <collision>rear_right_flipper_collision_middle_bar</collision>
      </contact>
    </sensor>
  </link>
  <joint name="rear_right_flipper_j" type="continuous">
    <parent link="right_track"/>
    <child link="rear_right_flipper"/>
    <axis xyz="0 1 0"/>
    <origin rpy="0 -0.1937 0" xyz="-0.25 -0.0735 0.0195"/>
  </joint>
  <link name="front_left_flipper_end_point"/>
  <joint name="front_left_flipper_end_point_j" type="fixed">
    <parent link="front_left_flipper"/>
    <child link="front_left_flipper_end_point"/>
    <origin rpy="0 0.1937 0" xyz="0.3476 0 0"/>
  </joint>
  <link name="front_right_flipper_end_point"/>
  <joint name="front_right_flipper_end_point_j" type="fixed">
    <parent link="front_right_flipper"/>
    <child link="front_right_flipper_end_point"/>
    <origin rpy="0 0.1937 0" xyz="0.3476 0 0"/>
  </joint>
  <link name="laser">
    <visual>
      <origin rpy="1.5707963267 0 -1.5707963267" xyz="0 0 0"/>
      <geometry>
        <mesh filename="package://nifti_robot_description/meshes/laser.dae" scale="1.0 1.0 1.0"/>
      </geometry>
    </visual>
    <collision>
      <origin rpy="1.5707963267 0 -1.5707963267" xyz="0 0 -0.04"/>
      <geometry>
        <box size="0.1159 0.16826 0.1159"/>
      </geometry>
    </collision>
    <inertial>
      <origin rpy="0 0 0" xyz="0 0 -0.07"/>
      <mass value="1.1"/>
      <inertia ixx="0.0031194" ixy="-2.221e-06" ixz="-1.1577e-06" iyy="0.0031389" iyz="-1.153e-05" izz="0.0017656"/>
    </inertial>
  </link>
  <joint name="laser_j" type="revolute">
    <parent link="base_link"/>
    <child link="laser"/>
    <axis xyz="1 0 0"/>
    <dynamics damping="10000000"/>
    <origin rpy="3.1415927 0 0" xyz="0.2502 0.0 0.1407"/>
    <limit effort="0" lower="-2.3561945" upper="2.3561945" velocity="4"/>
  </joint>
  <link name="imu">
    <visual>
      <origin rpy="0 0 0" xyz="0 0 0"/>
      <geometry>
        <box size="0.05 0.05 0.05"/>
      </geometry>
      <material name="invisible_color">
        <color rgba="1 0 0 0.5"/>
      </material>
    </visual>
    <inertial>
      <origin rpy="0 0 0" xyz="0 0 0"/>
      <mass value="1e-5"/>
      <inertia ixx="1e-3" ixy="1e-6" ixz="1e-6" iyy="1e-3" iyz="1e-6" izz="1e-3"/>
    </inertial>
  </link>
  <joint name="imu_j" type="fixed">
    <parent link="base_link"/>
    <child link="imu"/>
    <origin rpy="3.141592 0 0" xyz="0 0 0.1500"/>
  </joint>
  <link name="omnicam">
    <visual>
      <origin rpy="0 0 0" xyz="0 0 0"/>
      <geometry>
        <mesh filename="package://nifti_robot_description/meshes/omnicam.dae" scale="1.0 1.0 1.0"/>
      </geometry>
    </visual>
    <collision>
      <origin rpy="0 0 0" xyz="-0.003 -0.0015 0.003"/>
      <geometry>
        <cylinder length="0.137" radius="0.068"/>
      </geometry>
    </collision>
    <inertial>
      <origin rpy="0 0 0" xyz="0 0 0"/>
      <mass value="2.414"/>
      <inertia ixx="0.0023726" ixy="-3.0562e-06" ixz="-2.3418e-06" iyy="0.0023716" iyz="5.1202e-06" izz="0.0016667"/>
    </inertial>
  </link>
  <joint name="omnicam_j" type="fixed">
    <parent link="top_box"/>
    <child link="omnicam"/>
    <origin rpy="0 0 -0.628318530" xyz="0.0023 -0.0017 0.1292"/>
  </joint>
</robot>

